Workbook

Sheet README
A1: 3MAPGOT CALCULATOR v2.3 — per-second 10%-EV lines (built from dense MC grid, n=30k, seed 7)
A2: Provenance: fits.json (both seasons, exposure-based), coach attenuation 0.355, context multipliers home 1.34 / fav 1.07 / dog 0.64.
A4: WHAT'S NEW (Seb rulings 2026-07-25):
A5: - Any time between 3:00 and 15:00 accepted (bilinear interpolation on a 20-second mesh).
A6: - LINE output per market: the American line at which the bet clears the edge in cell D8 (default +10% EV). Bet only at that number or better.
A7: - Coach policy: NO stake mandates. Coaches with <5 real chances are flagged RISKY in COACHES col G — your sizing call.
A8: - Status: NO-GO for real money (Seb). This is a research/paper tool until 99% confidence.
A10: VALIDATION (blind 25-26, betting EVERY spot at the exact 10%-EV line, game-cluster CIs):
A11: - leader TT over: realized ROI +21.3%, CI [+7.3%, +35.9%] — PROVEN >10%
A12: - game total over: realized ROI +9.3%, CI [-0.9%, +20.1%] — positive, 10% not proven
A13: - leader -3.5: realized ROI +2.5%, CI [-13.8%, +19.3%] — CI includes 0: treat edges as optimistic
A15: STANDING WARNINGS:
... A19: - Timing: Roy-type late pullers shift the curve; production shifts applied in the fits, not user-adjustable here.

Sheet PRICES
A1: key | B1: R | C1: time | D1: state | E1: tier | F1: P_total_ge1 | G1: P_total_ge2 | H1: P_leader_ge1 | I1: P_margin_ge4 | J1: P_leader_ge2
A2: 900|not_pulled_EV|0.25 | B2: 900 | C2: 15:00 | D2: not_pulled_EV | E2: 0.25 | F2: 0.7932 | G2: 0.506 | H2: 0.6796 | I2: 0.431 | J2: 0.2425
A3: 900|not_pulled_EV|0.40 | B3: 900 | C3: 15:00 | D3: not_pulled_EV | E3: 0.4 | F3: 0.8303 | G3: 0.519 | H3: 0.7157 | I3: 0.4682 | J3: 0.2578
A4: 900|not_pulled_EV|0.55 | B4: 900 | C4: 15:00 | D4: not_pulled_EV | E4: 0.55 | F4: 0.8668 | G4: 0.5313 | H4: 0.7504 | I4: 0.5057 | J4: 0.2736
A5: 900|not_pulled_EV|0.70 | B5: 900 | C5: 15:00 | D5: not_pulled_EV | E5: 0.7 | F5: 0.9006 | G5: 0.5428 | H5: 0.7827 | I5: 0.54 | J5: 0.2879
A6: 900|not_pulled_EV|0.85 | B6: 900 | C6: 15:00 | D6: not_pulled_EV | E6: 0.85 | F6: 0.9322 | G6: 0.5548 | H6: 0.8132 | I6: 0.5746 | J6: 0.3048
A7: 900|not_pulled_PP|0.25 | B7: 900 | C7: 15:00 | D7: not_pulled_PP | E7: 0.25 | F7: 0.7978 | G7: 0.5202 | H7: 0.6746 | I7: 0.4099 | J7: 0.238
A8: 900|not_pulled_PP|0.40 | B8: 900 | C8: 15:00 | D8: not_pulled_PP | E8: 0.4 | F8: 0.8339 | G8: 0.5329 | H8: 0.7095 | I8: 0.4469 | J8: 0.254
A9: 900|not_pulled_PP|0.55 | B9: 900 | C9: 15:00 | D9: not_pulled_PP | E9: 0.55 | F9: 0.8692 | G9: 0.5449 | H9: 0.7432 | I9: 0.4838 | J9: 0.27
A10: 900|not_pulled_PP|0.70 | B10: 900 | C10: 15:00 | D10: not_pulled_PP | E10: 0.7 | F10: 0.9025 | G10: 0.5565 | H10: 0.7751 | I10: 0.5183 | J10: 0.285
A11: 900|not_pulled_PP|0.85 | B11: 900 | C11: 15:00 | D11: not_pulled_PP | E11: 0.85 | F11: 0.9335 | G11: 0.5686 | H11: 0.8048 | I11: 0.552 | J11: 0.3021
A12: 900|pulled|0.25 | B12: 900 | C12: 15:00 | D12: pulled | E12: 0.25 | F12: 0.9982 | G12: 0.754 | H12: 0.9773 | I12: 0.8074 | J12: 0.6598
A13: 900|pulled|0.40 | B13: 900 | C13: 15:00 | D13: pulled | E13: 0.4 | F13: 0.9982 | G13: 0.754 | H13: 0.9773 | I13: 0.8074 | J13: 0.6598
... A556: 180|pulled|0.85 | B556: 180 | C556: 3:00 | D556: pulled | E556: 0.85 | F556: 0.8503 | G556: 0.1611 | H556: 0.7078 | I556: 0.6129 | J556: 0.0495

Sheet LOOKUP
A1: LIVE LOOKUP — fill the 6 yellow cells
A3: Time remaining (any mm:ss from 3:00 to 15:00) | D3: 10:00
A4: State (not_pulled_EV / not_pulled_PP / pulled) | D4: not_pulled_EV
A5: Coach PRODUCTION m (COACHES col E; unknown = 1.00) | D5: 1
A6: Trailing team at HOME? (y/n — 'n' for low-tail coaches) | D6: n
A7: Trailing team is... (fav / even / dog) by standings | D7: even
A8: Edge required (0.10 = +10% EV) | D8: 0.1
A9: R secs / m_total: | D9: =MAX(180,MIN(900,VALUE(LEFT(D3,FIND(":",D3)-1))*60+VALUE(MID(D3,FIND(":",D3)+1,2)))) | E9: =D5*IF(LOWER(D6)="y",1.34,1)*IF(LOWER(D7)="fav",1.07,IF(LOWER(D7)="dog",0.64,1))
A10: tier lo/hi/weight: | D10: =IF(E9<=0.8,0.55,IF(E9<=1,0.8,IF(E9<=1.3,1,IF(E9<=1.85,1.3,1.85)))) | E10: =IF(E9<=0.8,0.8,IF(E9<=1,1,IF(E9<=1.3,1.3,IF(E9<=1.85,1.85,2.4)))) | F10: =MAX(0,MIN(1,(E9-D10)/(E10-D10)))
A11: R lo/hi/weight: | D11: =MIN(880,FLOOR(D9,20)) | E11: =D11+20 | F11: =MAX(0,MIN(1,(D9-D11)/20))
A12: corner keys: | B12: =D11&"|"&D4&"|"&TEXT(D10,"0.00") | C12: =D11&"|"&D4&"|"&TEXT(E10,"0.00") | D12: =E11&"|"&D4&"|"&TEXT(D10,"0.00") | E12: =E11&"|"&D4&"|"&TEXT(E10,"0.00")
A14: MARKET | D14: PROBABILITY | E14: LINE for +edge EV
A15: P(any more goal) — game total over | D15: =(1-$F$11)*((1-$F$10)*B22+$F$10*C22)+$F$11*((1-$F$10)*D22+$F$10*E22) | E15: =IF(D15<=0,"n/a",IF((1+$D$8-D15)/D15>=1,"+"&TEXT(ROUND((1+$D$8-D15)/D15*100,0),"0"),"-"&TEXT(ROUND(100/((1+$D$8-D15)/D15),0),"0")))
A16: P(LEADER scores again) — team total over (model ~5pts LOW; Overs only) | D16: =(1-$F$11)*((1-$F$10)*B23+$F$10*C23)+$F$11*((1-$F$10)*D23+$F$10*E23) | E16: =IF(D16<=0,"n/a",IF((1+$D$8-D16)/D16>=1,"+"&TEXT(ROUND((1+$D$8-D16)/D16*100,0),"0"),"-"&TEXT(ROUND(100/((1+$D$8-D16)/D16),0),"0")))
A17: P(leader wins by 4+) — the -3.5 | D17: =(1-$F$11)*((1-$F$10)*B24+$F$10*C24)+$F$11*((1-$F$10)*D24+$F$10*E24) | E17: =IF(D17<=0,"n/a",IF((1+$D$8-D17)/D17>=1,"+"&TEXT(ROUND((1+$D$8-D17)/D17*100,0),"0"),"-"&TEXT(ROUND(100/((1+$D$8-D17)/D17),0),"0")))
A19: Warnings: | D19: =IF(AND(D4="pulled",D9>420),"EXTRAPOLATED — no real pulls this early","ok")
A21: helper: corner probabilities (do not edit)
A22: P(any more goal) | B22: =INDEX(PRICES!F:F,MATCH($B$12,PRICES!A:A,0)) | C22: =INDEX(PRICES!F:F,MATCH($C$12,PRICES!A:A,0)) | D22: =INDEX(PRICES!F:F,MATCH($D$12,PRICES!A:A,0)) | E22: =INDEX(PRICES!F:F,MATCH($E$12,PRICES!A:A,0))
A23: P(LEADER scores again) | B23: =INDEX(PRICES!H:H,MATCH($B$12,PRICES!A:A,0)) | C23: =INDEX(PRICES!H:H,MATCH($C$12,PRICES!A:A,0)) | D23: =INDEX(PRICES!H:H,MATCH($D$12,PRICES!A:A,0)) | E23: =INDEX(PRICES!H:H,MATCH($E$12,PRICES!A:A,0))
A24: P(leader wins by 4+) | B24: =INDEX(PRICES!I:I,MATCH($B$12,PRICES!A:A,0)) | C24: =INDEX(PRICES!I:I,MATCH($C$12,PRICES!A:A,0)) | D24: =INDEX(PRICES!I:I,MATCH($D$12,PRICES!A:A,0)) | E24: =INDEX(PRICES!I:I,MATCH($E$12,PRICES!A:A,0))

Sheet MANUAL_PRICES
A1: key | B1: R | C1: pullpct | D1: shift | E1: P_total_ge1 | F1: P_leader_ge1 | G1: P_margin_ge4
A2: 900|0.100|-60 | B2: 900 | C2: 0.1 | D2: -60 | E2: 0.7521 | F2: 0.6395 | G2: 0.391
A3: 900|0.100|0 | B3: 900 | C3: 0.1 | D3: 0 | E3: 0.7537 | F3: 0.6419 | G3: 0.3925
A4: 900|0.100|60 | B4: 900 | C4: 0.1 | D4: 60 | E4: 0.7552 | F4: 0.6441 | G4: 0.3944
A5: 900|0.100|120 | B5: 900 | C5: 0.1 | D5: 120 | E5: 0.7553 | F5: 0.6452 | G5: 0.3959
A6: 900|0.100|180 | B6: 900 | C6: 0.1 | D6: 180 | E6: 0.7554 | F6: 0.6462 | G6: 0.3969
A7: 900|0.300|-60 | B7: 900 | C7: 0.3 | D7: -60 | E7: 0.8008 | F7: 0.6849 | G7: 0.4393
A8: 900|0.300|0 | B8: 900 | C8: 0.3 | D8: 0 | E8: 0.8063 | F8: 0.692 | G8: 0.444
A9: 900|0.300|60 | B9: 900 | C9: 0.3 | D9: 60 | E9: 0.8086 | F9: 0.6974 | G9: 0.4474
A10: 900|0.300|120 | B10: 900 | C10: 0.3 | D10: 120 | E10: 0.8111 | F10: 0.7026 | G10: 0.4523
A11: 900|0.300|180 | B11: 900 | C11: 0.3 | D11: 180 | E11: 0.8108 | F11: 0.705 | G11: 0.455
A12: 900|0.500|-60 | B12: 900 | C12: 0.5 | D12: -60 | E12: 0.8456 | F12: 0.7259 | G12: 0.4844
A13: 900|0.500|0 | B13: 900 | C13: 0.5 | D13: 0 | E13: 0.8551 | F13: 0.7391 | G13: 0.4937
... A1296: 180|0.990|180 | B1296: 180 | C1296: 0.99 | D1296: 180 | E1296: 0.1833 | F1296: 0.1227 | G1296: 0.1041

Sheet MANUAL
A1: MANUAL COACH OVERRIDE — your own pull read, priced by the model
A3: Time remaining (any mm:ss from 3:00 to 15:00) | D3: 6:00
A4: YOUR expected pull % on this real chance (0.10-0.99) | D4: 0.695
A5: His typical pull time left (league = 4:19) | D5: 4:19
A6: Edge required | D6: 0.1
A8: R / shift secs (snapped to grid): | D8: =MAX(180,MIN(900,VALUE(LEFT(D3,FIND(":",D3)-1))*60+VALUE(MID(D3,FIND(":",D3)+1,2)))) | E8: =MAX(-60,MIN(180,VALUE(LEFT(D5,FIND(":",D5)-1))*60+VALUE(MID(D5,FIND(":",D5)+1,2))-259)) | F8: =INDEX({-60;0;60;120;180},MATCH(MIN(ABS({-60;0;60;120;180}-E8)),ABS({-60;0;60;120;180}-E8),0))
A9: R lo/hi/w: | D9: =MIN(880,FLOOR(D8,20)) | E9: =D9+20 | F9: =MAX(0,MIN(1,(D8-D9)/20))
A10: pull%% lo/hi/w: | D10: =MAX(0.1,INDEX({0.1;0.3;0.5;0.695;0.85;0.95;0.99},MATCH(MIN(MAX(D4,0.1),0.99),{0.1;0.3;0.5;0.695;0.85;0.95;0.99},1))) | E10: =MIN(0.99,INDEX({0.1;0.3;0.5;0.695;0.85;0.95;0.99},MIN(MATCH(D10,{0.1;0.3;0.5;0.695;0.85;0.95;0.99},0)+1,7))) | F10: =IF(E10=D10,0,MAX(0,MIN(1,(MIN(MAX(D4,0.1),0.99)-D10)/(E10-D10))))
A11: corner keys: | B11: =D9&"|"&TEXT(D10,"0.000")&"|"&F8 | C11: =D9&"|"&TEXT(E10,"0.000")&"|"&F8 | D11: =E9&"|"&TEXT(D10,"0.000")&"|"&F8 | E11: =E9&"|"&TEXT(E10,"0.000")&"|"&F8
A13: MARKET | D13: PROBABILITY | E13: LINE for +edge EV
A14: Game total OVER (any more goal) | D14: =(1-$F$9)*((1-$F$10)*B21+$F$10*C21)+$F$9*((1-$F$10)*D21+$F$10*E21) | E14: =IF(D14<=0,"n/a",IF((1+$D$6-D14)/D14>=1,"+"&TEXT(ROUND((1+$D$6-D14)/D14*100,0),"0"),"-"&TEXT(ROUND(100/((1+$D$6-D14)/D14),0),"0")))
A15: Leader TT OVER (Overs only; model ~5pts low) | D15: =(1-$F$9)*((1-$F$10)*B22+$F$10*C22)+$F$9*((1-$F$10)*D22+$F$10*E22) | E15: =IF(D15<=0,"n/a",IF((1+$D$6-D15)/D15>=1,"+"&TEXT(ROUND((1+$D$6-D15)/D15*100,0),"0"),"-"&TEXT(ROUND(100/((1+$D$6-D15)/D15),0),"0")))
A16: Leader -3.5 (wins by 4+) | D16: =(1-$F$9)*((1-$F$10)*B23+$F$10*C23)+$F$9*((1-$F$10)*D23+$F$10*E23) | E16: =IF(D16<=0,"n/a",IF((1+$D$6-D16)/D16>=1,"+"&TEXT(ROUND((1+$D$6-D16)/D16*100,0),"0"),"-"&TEXT(ROUND(100/((1+$D$6-D16)/D16),0),"0")))
A18: Notes: timing snapped to nearest grid step (max 30s, ~1pt effect). 100% pullers: use 0.99.
A19: 5v5 only — PP/pulled states not bettable (Seb rulings).
A20: Timing input: observed averages are opportunity-noise — if your read is from <10 pulls, enter something between his avg and 4:19.
A21: Game total OVER | B21: =INDEX(MANUAL_PRICES!E:E,MATCH($B$11,MANUAL_PRICES!A:A,0)) | C21: =INDEX(MANUAL_PRICES!E:E,MATCH($C$11,MANUAL_PRICES!A:A,0)) | D21: =INDEX(MANUAL_PRICES!E:E,MATCH($D$11,MANUAL_PRICES!A:A,0)) | E21: =INDEX(MANUAL_PRICES!E:E,MATCH($E$11,MANUAL_PRICES!A:A,0))
A22: Leader TT OVER | B22: =INDEX(MANUAL_PRICES!F:F,MATCH($B$11,MANUAL_PRICES!A:A,0)) | C22: =INDEX(MANUAL_PRICES!F:F,MATCH($C$11,MANUAL_PRICES!A:A,0)) | D22: =INDEX(MANUAL_PRICES!F:F,MATCH($D$11,MANUAL_PRICES!A:A,0)) | E22: =INDEX(MANUAL_PRICES!F:F,MATCH($E$11,MANUAL_PRICES!A:A,0))
A23: Leader -3.5 | B23: =INDEX(MANUAL_PRICES!G:G,MATCH($B$11,MANUAL_PRICES!A:A,0)) | C23: =INDEX(MANUAL_PRICES!G:G,MATCH($C$11,MANUAL_PRICES!A:A,0)) | D23: =INDEX(MANUAL_PRICES!G:G,MATCH($D$11,MANUAL_PRICES!A:A,0)) | E23: =INDEX(MANUAL_PRICES!G:G,MATCH($E$11,MANUAL_PRICES!A:A,0))

Sheet COACHES
A1: coach | B1: pulls | C1: expected | D1: m_EB | E1: m_PRODUCTION (use this) | F1: real chances | G1: flag
A2: Jared Bednar | B2: 9 | C2: 1.25 | D2: 3.386 | E2: 1.847 | F2: 28
A3: Dan Muse | B3: 8 | C3: 2.19 | D3: 2.386 | E3: 1.492 | F3: 20
A4: Joe Sacco | B4: 5 | C4: 1.08 | D4: 2.272 | E4: 1.452 | F4: 20
A5: Patrick Roy | B5: 12 | C5: 4.68 | D5: 2.097 | E5: 1.39 | F5: 40
A6: Craig Berube | B6: 15 | C6: 7.54 | D6: 1.781 | E6: 1.277 | F6: 51
A7: Peter Laviolette | B7: 3 | C7: 0.83 | D7: 1.764 | E7: 1.271 | F7: 20
A8: Glen Gulutzan | B8: 5 | C8: 2.36 | D8: 1.607 | E8: 1.215 | F8: 12
A9: Travis Green | B9: 11 | C9: 7.06 | D9: 1.435 | E9: 1.154 | F9: 34
A10: D.J. Smith | B10: 1 | C10: 0.12 | D10: 1.414 | E10: 1.147 | F10: 2 | G10: RISKY (<5 chances)
A11: Dan Bylsma | B11: 7 | C11: 4.57 | D11: 1.371 | E11: 1.132 | F11: 25
A12: Kris Knoblauch | B12: 7 | C12: 4.68 | D12: 1.348 | E12: 1.123 | F12: 36
A13: Lindy Ruff | B13: 11 | C13: 7.76 | D13: 1.332 | E13: 1.118 | F13: 47
A14: Joel Quenneville | B14: 3 | C14: 1.79 | D14: 1.32 | E14: 1.114 | F14: 22
A15: Jon Cooper | B15: 9 | C15: 6.48 | D15: 1.298 | E15: 1.106 | F15: 25
A16: Scott Arniel | B16: 6 | C16: 4.26 | D16: 1.278 | E16: 1.099 | F16: 39
A17: John Hynes | B17: 7 | C17: 5.68 | D17: 1.171 | E17: 1.061 | F17: 47
A18: Jeff Blashill | B18: 3 | C18: 2.27 | D18: 1.171 | E18: 1.061 | F18: 19
A19: Derek Lalonde | B19: 3 | C19: 2.39 | D19: 1.138 | E19: 1.049 | F19: 10
A20: Paul Maurice | B20: 7 | C20: 6.34 | D20: 1.079 | E20: 1.028 | F20: 46
A21: Martin St. Louis | B21: 6 | C21: 5.44 | D21: 1.075 | E21: 1.027 | F21: 36
A22: Adam Foote | B22: 8 | C22: 7.6 | D22: 1.042 | E22: 1.015 | F22: 39
... A25: Rick Tocchet | B25: 5 | C25: 5.5 | D25: 0.933 | E25: 0.976 | F25: 44
A26: Rick Bowness | B26: 0 | C26: 0.16 | D26: 0.925 | E26: 0.973 | F26: 4 | G26: RISKY (<5 chances)
A27: Drew Bannister | B27: 0 | C27: 0.22 | D27: 0.903 | E27: 0.966 | F27: 6
A28: Jim Hiller | B28: 4 | C28: 4.93 | D28: 0.865 | E28: 0.952 | F28: 22
A29: Peter DeBoer | B29: 1 | C29: 1.6 | D29: 0.833 | E29: 0.941 | F29: 17
A30: Bruce Cassidy | B30: 7 | C30: 8.98 | D30: 0.819 | E30: 0.936 | F30: 31
A31: Sheldon Keefe | B31: 8 | C31: 11.02 | D31: 0.768 | E31: 0.918 | F31: 47
A32: Brad Shaw | B32: 0 | C32: 0.65 | D32: 0.755 | E32: 0.913 | F32: 1 | G32: RISKY (<5 chances)
A33: Jim Montgomery | B33: 4 | C33: 6.16 | D33: 0.736 | E33: 0.906 | F33: 31
A34: Rod Brind'Amour | B34: 4 | C34: 6.31 | D34: 0.722 | E34: 0.901 | F34: 33
A35: Lane Lambert | B35: 4 | C35: 6.31 | D35: 0.722 | E35: 0.901 | F35: 28
A36: Ryan Warsofsky | B36: 5 | C36: 8.17 | D36: 0.688 | E36: 0.889 | F36: 52
A37: Marco Sturm | B37: 1 | C37: 2.44 | D37: 0.675 | E37: 0.885 | F37: 18
A38: Spencer Carbery | B38: 3 | C38: 5.85 | D38: 0.637 | E38: 0.871 | F38: 30
A39: Luke Richardson | B39: 0 | C39: 1.27 | D39: 0.611 | E39: 0.862 | F39: 8
A40: Greg Cronin | B40: 2 | C40: 4.54 | D40: 0.612 | E40: 0.862 | F40: 25
A41: AndrÃ© Tourigny | B41: 2 | C41: 5.84 | D41: 0.51 | E41: 0.826 | F41: 31
A42: Todd McLellan | B42: 2 | C42: 5.96 | D42: 0.502 | E42: 0.823 | F42: 36 | G42: LOW-TAIL: context mults OFF
...
